<?xml version="1.0" ?>
<!-- =================================================================================== -->
<!-- |    This document was autogenerated by xacro from mybot.xacro                    | -->
<!-- |    EDITING THIS FILE BY HAND IS NOT RECOMMENDED                                 | -->
<!-- =================================================================================== -->
<robot name="myrobot">
  <gazebo>
    <plugin filename="libgazebo_ros_diff_drive.so" name="differential_drive_controller">
      <legacyMode>false</legacyMode>
      <alwaysOn>true</alwaysOn>
      <updateRate>10</updateRate>
      <leftJoint>left_wheel_hinge</leftJoint>
      <rightJoint>right_wheel_hinge</rightJoint>
      <wheelSeparation>0.4</wheelSeparation>
      <wheelDiameter>0.2</wheelDiameter>
      <torque>10000</torque>
      <commandTopic>cmd_vel</commandTopic>
      <odometryTopic>odom</odometryTopic>
      <odometryFrame>odom</odometryFrame>
      <robotBaseFrame>chassis</robotBaseFrame>
      <rosDebugLevel>na</rosDebugLevel>
      <publishWheelTF>false</publishWheelTF>
      <publishOdomTF>true</publishOdomTF>
      <publishWheelJointState>false</publishWheelJointState>
      <wheelAcceleration>0</wheelAcceleration>
      <wheelTorque>5</wheelTorque>
      <odometrySource>world</odometrySource>
      <publishTf>1</publishTf>
    </plugin>
  </gazebo>
  <gazebo reference="chassis">
    <material>Gazebo/Orange</material>
  </gazebo>
  <gazebo reference="right_wheel">
    <material>Gazebo/FlatBlack</material>
  </gazebo>
  <gazebo reference="left_wheel">
    <material>Gazebo/FlatBlack</material>
  </gazebo>
  <gazebo reference="camera">
    <material>Gazebo/Green</material>
    <sensor name="camera1" type="camera">
      <update_rate>30.0</update_rate>
      <camera name="head">
        <horizontal_fov>1.3962634</horizontal_fov>
        <image>
          <width>800</width>
          <height>800</height>
          <format>R8G8B8</format>
        </image>
        <clip>
          <near>0.02</near>
          <far>300</far>
        </clip>
      </camera>
      <plugin filename="libgazebo_ros_camera.so" name="camera_controller">
        <alwaysOn>true</alwaysOn>
        <updateRate>0.0</updateRate>
        <cameraName>mybot/camera1</cameraName>
        <imageTopicName>image_raw</imageTopicName>
        <cameraInfoTopicName>camera_info</cameraInfoTopicName>
        <frameName>camera</frameName>
        <hackBaseline>0.07</hackBaseline>
        <distortionK1>0.0</distortionK1>
        <distortionK2>0.0</distortionK2>
        <distortionK3>0.0</distortionK3>
        <distortionT1>0.0</distortionT1>
        <distortionT2>0.0</distortionT2>
      </plugin>
    </sensor>
  </gazebo>
  <!-- hokuyo -->
  <gazebo reference="hokuyo">
    <sensor name="head_hokuyo_sensor" type="gpu_ray">
      <pose>0 0 0 0 0 0</pose>
      <visualize>true</visualize>
      <update_rate>40</update_rate>
      <ray>
        <scan>
          <horizontal>
            <samples>720</samples>
            <resolution>1</resolution>
            <min_angle>-1.570796</min_angle>
            <max_angle>1.570796</max_angle>
          </horizontal>
        </scan>
        <range>
          <min>0.10</min>
          <max>30.0</max>
          <resolution>0.01</resolution>
        </range>
        <noise>
          <type>gaussian</type>
          <!-- Noise parameters based on published spec for Hokuyo laser
               achieving "+-30mm" accuracy at range < 10m.  A mean of 0.0m and
               stddev of 0.01m will put 99.7% of samples within 0.03m of the true
               reading. -->
          <mean>0.0</mean>
          <stddev>0.01</stddev>
        </noise>
      </ray>
      <plugin filename="libgazebo_ros_gpu_laser.so" name="gazebo_ros_head_hokuyo_controller">
        <topicName>/mybot/laser/scan</topicName>
        <frameName>hokuyo</frameName>
      </plugin>
    </sensor>
  </gazebo>
  <material name="black">
    <color rgba="0.0 0.0 0.0 1.0"/>
  </material>
  <material name="blue">
    <color rgba="0.0 0.0 0.8 1.0"/>
  </material>
  <material name="green">
    <color rgba="0.0 0.8 0.0 1.0"/>
  </material>
  <material name="grey">
    <color rgba="0.2 0.2 0.2 1.0"/>
  </material>
  <material name="orange">
    <color rgba="1.0 0.4235294117647059 0.0392156862745098 1.0"/>
  </material>
  <material name="brown">
    <color rgba="0.8705882352941177 0.8117647058823529 0.7647058823529411 1.0"/>
  </material>
  <material name="red">
    <color rgba="0.8 0.0 0.0 1.0"/>
  </material>
  <material name="white">
    <color rgba="1.0 1.0 1.0 1.0"/>
  </material>
  <!--macro name="cylinder_inertia" params="m r h">
    <inertia  ixx="${m*(3*r*r+h*h)/12}" ixy = "0" ixz = "0"
      iyy="${m*(3*r*r+h*h)/12}" iyz = "0"
      izz="${m*r*r/2}"
    />
  </macro>
  <macro name="box_inertia" params="m x y z">
    <inertia  ixx="${m*(y*y+z*z)/12}" ixy = "0" ixz = "0"
      iyy="${m*(x*x+z*z)/12}" iyz = "0"
      izz="${m*(x*x+z*z)/12}"
    />
  </macro>
  <macro name="sphere_inertia" params="m r">
    <inertia  ixx="${2*m*r*r/5}" ixy = "0" ixz = "0"
      iyy="${2*m*r*r/5}" iyz = "0"
      izz="${2*m*r*r/5}"
    />
  </macro>
  <macro name="wheel" params="lr tY">
    <link name="${lr}_wheel">
      <collision>
        <origin xyz="0 0 0" rpy="0 ${PI/2} ${PI/2}" />
        <geometry>
          <cylinder length="${wheelWidth}" radius="${wheelRadius}"/>
        </geometry>
      </collision>
      <visual>
        <origin xyz="0 0 0" rpy="0 ${PI/2} ${PI/2}" />
        <geometry>
          <cylinder length="${wheelWidth}" radius="${wheelRadius}"/>
        </geometry>
        <material name="black"/>
      </visual>
      <inertial>
        <origin xyz="0 0 0" rpy="0 ${PI/2} ${PI/2}" />
        <mass value="${wheelMass}"/>
        <cylinder_inertia m="${wheelMass}" r="${wheelRadius}" h="${wheelWidth}"/>
      </inertial>
    </link>
    <gazebo reference="${lr}_wheel">
      <mu1 value="1.0"/>
      <mu2 value="1.0"/>
      <kp  value="10000000.0" />
      <kd  value="1.0" />
      <fdir1 value="1 0 0"/>
      <material>Gazebo/Black</material>
    </gazebo>
    <joint name="${lr}_wheel_hinge" type="continuous">
      <parent link="chassis"/>
      <child link="${lr}_wheel"/>
    <origin xyz="${-wheelPos+chassisLength/2} ${tY*wheelWidth/2+tY*chassisWidth/2} ${wheelRadius}" rpy="0 0 0" />
      <axis xyz="0 1 0" rpy="0 0 0" />
      <limit effort="10000" velocity="10000"/>
      <joint_properties damping="0.0" friction="0.0"/>
    </joint>
    <transmission name="${lr}_trans">
      <type>transmission_interface/SimpleTransmission</type>
      <joint name="${lr}_wheel_hinge">
        <hardwareInterface>EffortJointInterface</hardwareInterface>
      </joint>
      <actuator name="${lr}Motor">
        <hardwareInterface>EffortJointInterface</hardwareInterface>
        <mechanicalReduction>10</mechanicalReduction>
      </actuator>
    </transmission>
  </macro-->
  <link name="chassis">
    <pose>0 0 0.1 0 0 0</pose>
    <inertial>
      <mass value="15.0"/>
      <origin rpy=" 0 0 0" xyz="0.0 0 0"/>
      <inertia ixx="0.1" ixy="0" ixz="0" iyy="0.1" iyz="0" izz="0.1"/>
    </inertial>
    <collision name="collision">
      <geometry>
        <mesh filename="package://diff_drive_bot/meshes/base_supporti.stl"/>
        <!-- <box size=".4 .2 .1"/> -->
      </geometry>
    </collision>
    <visual name="chassis_visual">
      <origin rpy=" 0 0 0" xyz="0 0 0"/>
      <geometry>
        <mesh filename="package://diff_drive_bot/meshes/base_supporti.stl"/>
        <!-- <box size=".4 .2 .1"/> -->
      </geometry>
    </visual>
  </link>
  <link name="left_wheel">
    <!--origin xyz="0.1 0.13 0.1" rpy="0 1.5707 1.5707"/-->
    <collision name="collision">
      <origin rpy="-1.5708 -0 0" xyz="0 0 0.025"/>
      <geometry>
        <mesh filename="package://diff_drive_bot/meshes/wheel.stl"/>
        <!-- <cylinder radius="0.1" length="0.05"/> -->
      </geometry>
    </collision>
    <visual name="left_wheel_visual">
      <origin rpy="-1.5708 -0 0" xyz="0 0 0.025"/>
      <geometry>
        <mesh filename="package://diff_drive_bot/meshes/wheel.stl"/>
        <!-- <cylinder radius="0.1" length="0.05"/> -->
      </geometry>
    </visual>
    <inertial>
      <origin rpy="0 0 0" xyz="-2.18305e-18 5.73556e-20 -6.93889e-18"/>
      <mass value="5"/>
      <inertia ixx=".1" ixy="0.0" ixz="0.0" iyy=".1" iyz="0.0" izz=".1"/>
    </inertial>
  </link>
  <joint name="left_wheel_hinge" type="continuous">
    <origin rpy="-1.5708 -0 1.28103e-16" xyz="-0.000196272 -0.203923 0.035"/>
    <!--origin xyz="0.1 0.13 0" rpy="0 1.5707 1.5707"/-->
    <child link="left_wheel"/>
    <parent link="chassis"/>
    <axis rpy="0 0 0" xyz="0 0 1"/>
    <limit effort="10000" velocity="1000"/>
    <joint_properties damping="1.0" friction="1.0"/>
  </joint>
  <link name="right_wheel">
    <!--origin xyz="0.1 -0.13 0.1" rpy="0 1.5707 1.5707"/-->
    <collision name="collision">
      <origin rpy="-1.5708 -0 0" xyz="0 0 0.025"/>
      <geometry>
        <mesh filename="package://diff_drive_bot/meshes/wheel.stl"/>
        <!-- <cylinder radius="0.1" length="0.05"/> -->
      </geometry>
    </collision>
    <visual name="right_wheel_visual">
      <origin rpy="-1.5708 -0 0" xyz="0 0 0.025"/>
      <geometry>
        <!-- <cylinder radius="0.1" length="0.05"/> -->
        <mesh filename="package://diff_drive_bot/meshes/wheel.stl"/>
      </geometry>
    </visual>
    <inertial>
      <origin rpy="0 1.5707 1.5707" xyz="0 0 0"/>
      <mass value="5"/>
      <inertia ixx=".1" ixy="0.0" ixz="0.0" iyy=".1" iyz="0.0" izz=".1"/>
    </inertial>
  </link>
  <joint name="right_wheel_hinge" type="continuous">
    <origin rpy="-1.5708 -0 1.28103e-16" xyz="-0.000196272 0.203923 0.035"/>
    <!--origin xyz="0.1 -0.13 0" rpy="0 1.5707 1.5707"/-->
    <child link="right_wheel"/>
    <parent link="chassis"/>
    <axis rpy="0 0 0" xyz="0 0 1"/>
    <limit effort="10000" velocity="1000"/>
    <joint_properties damping="1.0" friction="1.0"/>
  </joint>
  <!-- ************************************************************************** -->
  <link name="camera">
    <collision>
      <origin rpy="0 0 0" xyz="0 0 0"/>
      <geometry>
        <box size="0.05 0.05 0.05"/>
      </geometry>
    </collision>
    <visual>
      <origin rpy="0 0 0" xyz="0 0 0"/>
      <geometry>
        <box size="0.05 0.05 0.05"/>
      </geometry>
      <material name="green"/>
    </visual>
    <inertial>
      <mass value="0.1"/>
      <origin rpy="0 0 0" xyz="0 0 0"/>
      <box_inertia m="0.1" x="0.05" y="0.05" z="0.05"/>
      <inertia ixx="1e-6" ixy="0" ixz="0" iyy="1e-6" iyz="0" izz="1e-6"/>
    </inertial>
  </link>
  <joint name="camera_joint" type="fixed">
    <axis xyz="0 1 0"/>
    <origin rpy="0 0 0" xyz=".2 0 0.75"/>
    <parent link="chassis"/>
    <child link="camera"/>
  </joint>
  <joint name="hokuyo_joint" type="fixed">
    <axis xyz="0 1 0"/>
    <origin rpy="0 0 0" xyz=".15 0 0.75"/>
    <parent link="chassis"/>
    <child link="hokuyo"/>
  </joint>
  <!-- Hokuyo Laser -->
  <link name="hokuyo">
    <collision>
      <origin rpy="0 0 0" xyz="0 0 0.5"/>
      <geometry>
        <box size="0.1 0.1 0.1"/>
      </geometry>
    </collision>
    <visual>
      <origin rpy="0 0 0" xyz="0 0 0.5"/>
      <geometry>
        <mesh filename="package://diff_drive_bot/meshes/hokuyo.dae"/>
      </geometry>
    </visual>
    <inertial>
      <mass value="1e-5"/>
      <origin rpy="0 0 0" xyz="0 0 0.5"/>
      <inertia ixx="1e-6" ixy="0" ixz="0" iyy="1e-6" iyz="0" izz="1e-6"/>
    </inertial>
  </link>
</robot>

